<robot name="diff_drive">

    <material name="black">
        <color rgba="0 0 0 1"/>
    </material>

    <material name="white">
        <color rgba="1 1 1 1"/>
    </material>

    <material name="gray">
        <color rgba="0.4 0.4 0.4 1"/>
    </material>

    <link name="base">
        <visual>
            <geometry>
                <box size="0.3 0.4 0.1"/>
            </geometry>
            <material name="black"/>
        </visual>
        <inertial>
            <mass value="1.0"/>
            <inertia ixx="1.0"  ixy="0"  ixz="0" iyy="1.0" iyz="0" izz="1.0" />
        </inertial>
    </link>

    <joint name="right_front_wheel_joint" type="continuous">
        <axis xyz="0 0 -1"/>
        <parent link="base"/>
        <child link="right_front_wheel"/>
        <origin rpy="0 1.57079632679 0" xyz="0.15 -0.2 -0.05"/>
        <limit effort="100" velocity="100"/>
        <joint_properties damping="0.0" friction="0.0"/>
    </joint>

    <link name="right_front_wheel">
    <visual>
      <geometry>
        <cylinder length=".05" radius="0.05"/>
      </geometry>
      <material name="gray"/>
    </visual>
    <collision>
      <geometry>
        <cylinder length=".05" radius="0.05"/>
      </geometry>
    </collision>
    <inertial>
      <mass value="1"/>
      <inertia ixx="1.0" ixy="0.0" ixz="0.0" iyy="1.0" iyz="0.0" izz="1.0"/>
    </inertial>
  </link>

  <joint name="left_front_wheel_joint" type="continuous">
    <axis xyz="0 0 -1"/>
    <parent link="base"/>
    <child link="left_front_wheel"/>
    <origin rpy="0 1.57079632679 0" xyz="-0.15 -0.2 -0.05"/>
    <limit effort="100" velocity="100"/>
    <joint_properties damping="0.0" friction="0.0"/>
  </joint>

  <link name="left_front_wheel">
    <visual>
      <geometry>
        <cylinder length=".05" radius="0.05"/>
      </geometry>
      <material name="gray"/>
    </visual>
    <collision>
      <geometry>
        <cylinder length=".05" radius="0.05"/>
      </geometry>
    </collision>
    <inertial>
      <mass value="1"/>
      <inertia ixx="1.0" ixy="0.0" ixz="0.0" iyy="1.0" iyz="0.0" izz="1.0"/>
    </inertial>
  </link>

  <joint name="castor_wheel_joint" type="spherical">
    <axis xyz="1 1 1"/>
    <parent link="base"/>
    <child link="castor_wheel"/>
    <origin rpy="0 0 0" xyz="0.0 0.2 -0.05"/>
    <limit effort="100" velocity="100"/>
    <joint_properties damping="0.0" friction="0.0"/>
  </joint>

  <link name="castor_wheel">
    <visual>
      <geometry>
        <sphere radius="0.05"/>
      </geometry>
      <material name="gray"/>
    </visual>
    <collision>
      <geometry>
        <sphere radius="0.05"/>
      </geometry>
    </collision>
    <inertial>
      <mass value="1"/>
      <inertia ixx="1.0" ixy="0.0" ixz="0.0" iyy="1.0" iyz="0.0" izz="1.0"/>
    </inertial>
  </link>

</robot>